[2025-09-23 16:10:11,540 ] tensorflow - DEBUG - Falling back to TensorFlow client; we recommended you install the Cloud TPU client directly with pip install cloud-tpu-client.
[2025-09-23 16:10:12,850 ] h5py._conv - DEBUG - Creating converter from 7 to 5
[2025-09-23 16:10:12,850 ] h5py._conv - DEBUG - Creating converter from 5 to 7
[2025-09-23 16:10:12,850 ] h5py._conv - DEBUG - Creating converter from 7 to 5
[2025-09-23 16:10:12,850 ] h5py._conv - DEBUG - Creating converter from 5 to 7
[2025-09-23 16:10:17,207 ] asyncio - DEBUG - Using proactor: IocpProactor
[2025-09-23 16:10:17,230 ] uvicorn.error - INFO - Started server process [12908]
[2025-09-23 16:10:17,231 ] uvicorn.error - INFO - Waiting for application startup.
[2025-09-23 16:10:17,235 ] uvicorn.error - INFO - Application startup complete.
[2025-09-23 16:10:17,237 ] uvicorn.error - INFO - Uvicorn running on http://0.0.0.0:8000 (Press CTRL+C to quit)
[2025-09-23 16:10:39,816 ] root - INFO - Running full prediction pipeline
[2025-09-23 16:10:39,816 ] root - INFO - Looking for model at: artifacts/PredictModel\model.h5
[2025-09-23 16:10:39,817 ] root - ERROR - Model file not found at artifacts/PredictModel\model.h5
[2025-09-23 16:10:39,824 ] uvicorn.error - ERROR - Exception in ASGI application
Traceback (most recent call last):
  File "C:\Users\MD RABIBUL ISLAM\Desktop\NLP_Project\hate_spech\pipeline\prediction_pipeline.py", line 57, in get_model_from_local
    raise FileNotFoundError(f"Model file not found at {self.model_path}")
FileNotFoundError: Model file not found at artifacts/PredictModel\model.h5

The above exception was the direct cause of the following exception:

Traceback (most recent call last):
  File "C:\Users\MD RABIBUL ISLAM\Desktop\NLP_Project\hate_spech\pipeline\prediction_pipeline.py", line 84, in predict
    model_path = self.get_model_from_local()
  File "C:\Users\MD RABIBUL ISLAM\Desktop\NLP_Project\hate_spech\pipeline\prediction_pipeline.py", line 61, in get_model_from_local
    raise CustomException(e, sys) from e
hate_spech.exception.CustomException: Error occurred in python script [C:\Users\MD RABIBUL ISLAM\Desktop\NLP_Project\hate_spech\pipeline\prediction_pipeline.py] at line number [57] with error message [Model file not found at artifacts/PredictModel\model.h5]

The above exception was the direct cause of the following exception:

Traceback (most recent call last):
  File "C:\Users\MD RABIBUL ISLAM\Desktop\NLP_Project\hate_spech\pipeline\prediction_pipeline.py", line 108, in run_pipeline
    result = self.predict(text)
  File "C:\Users\MD RABIBUL ISLAM\Desktop\NLP_Project\hate_spech\pipeline\prediction_pipeline.py", line 100, in predict
    raise CustomException(e, sys) from e
hate_spech.exception.CustomException: Error occurred in python script [C:\Users\MD RABIBUL ISLAM\Desktop\NLP_Project\hate_spech\pipeline\prediction_pipeline.py] at line number [84] with error message [Error occurred in python script [C:\Users\MD RABIBUL ISLAM\Desktop\NLP_Project\hate_spech\pipeline\prediction_pipeline.py] at line number [57] with error message [Model file not found at artifacts/PredictModel\model.h5]]

The above exception was the direct cause of the following exception:

Traceback (most recent call last):
  File "C:\Users\MD RABIBUL ISLAM\Desktop\NLP_Project\app.py", line 43, in predict_route
    text = obj.run_pipeline(text)
  File "C:\Users\MD RABIBUL ISLAM\Desktop\NLP_Project\hate_spech\pipeline\prediction_pipeline.py", line 112, in run_pipeline
    raise CustomException(e, sys) from e
hate_spech.exception.CustomException: Error occurred in python script [C:\Users\MD RABIBUL ISLAM\Desktop\NLP_Project\hate_spech\pipeline\prediction_pipeline.py] at line number [108] with error message [Error occurred in python script [C:\Users\MD RABIBUL ISLAM\Desktop\NLP_Project\hate_spech\pipeline\prediction_pipeline.py] at line number [84] with error message [Error occurred in python script [C:\Users\MD RABIBUL ISLAM\Desktop\NLP_Project\hate_spech\pipeline\prediction_pipeline.py] at line number [57] with error message [Model file not found at artifacts/PredictModel\model.h5]]]

The above exception was the direct cause of the following exception:

Traceback (most recent call last):
  File "C:\Users\MD RABIBUL ISLAM\miniconda3\envs\hate-spech\lib\site-packages\uvicorn\protocols\http\h11_impl.py", line 404, in run_asgi
    result = await app(  # type: ignore[func-returns-value]
  File "C:\Users\MD RABIBUL ISLAM\miniconda3\envs\hate-spech\lib\site-packages\uvicorn\middleware\proxy_headers.py", line 78, in __call__
    return await self.app(scope, receive, send)
  File "C:\Users\MD RABIBUL ISLAM\miniconda3\envs\hate-spech\lib\site-packages\fastapi\applications.py", line 269, in __call__
    await super().__call__(scope, receive, send)
  File "C:\Users\MD RABIBUL ISLAM\miniconda3\envs\hate-spech\lib\site-packages\starlette\applications.py", line 124, in __call__
    await self.middleware_stack(scope, receive, send)
  File "C:\Users\MD RABIBUL ISLAM\miniconda3\envs\hate-spech\lib\site-packages\starlette\middleware\errors.py", line 184, in __call__
    raise exc
  File "C:\Users\MD RABIBUL ISLAM\miniconda3\envs\hate-spech\lib\site-packages\starlette\middleware\errors.py", line 162, in __call__
    await self.app(scope, receive, _send)
  File "C:\Users\MD RABIBUL ISLAM\miniconda3\envs\hate-spech\lib\site-packages\starlette\exceptions.py", line 93, in __call__
    raise exc
  File "C:\Users\MD RABIBUL ISLAM\miniconda3\envs\hate-spech\lib\site-packages\starlette\exceptions.py", line 82, in __call__
    await self.app(scope, receive, sender)
  File "C:\Users\MD RABIBUL ISLAM\miniconda3\envs\hate-spech\lib\site-packages\fastapi\middleware\asyncexitstack.py", line 21, in __call__
    raise e
  File "C:\Users\MD RABIBUL ISLAM\miniconda3\envs\hate-spech\lib\site-packages\fastapi\middleware\asyncexitstack.py", line 18, in __call__
    await self.app(scope, receive, send)
  File "C:\Users\MD RABIBUL ISLAM\miniconda3\envs\hate-spech\lib\site-packages\starlette\routing.py", line 670, in __call__
    await route.handle(scope, receive, send)
  File "C:\Users\MD RABIBUL ISLAM\miniconda3\envs\hate-spech\lib\site-packages\starlette\routing.py", line 266, in handle
    await self.app(scope, receive, send)
  File "C:\Users\MD RABIBUL ISLAM\miniconda3\envs\hate-spech\lib\site-packages\starlette\routing.py", line 65, in app
    response = await func(request)
  File "C:\Users\MD RABIBUL ISLAM\miniconda3\envs\hate-spech\lib\site-packages\fastapi\routing.py", line 227, in app
    raw_response = await run_endpoint_function(
  File "C:\Users\MD RABIBUL ISLAM\miniconda3\envs\hate-spech\lib\site-packages\fastapi\routing.py", line 160, in run_endpoint_function
    return await dependant.call(**values)
  File "C:\Users\MD RABIBUL ISLAM\Desktop\NLP_Project\app.py", line 46, in predict_route
    raise CustomException(e, sys) from e
hate_spech.exception.CustomException: Error occurred in python script [C:\Users\MD RABIBUL ISLAM\Desktop\NLP_Project\app.py] at line number [43] with error message [Error occurred in python script [C:\Users\MD RABIBUL ISLAM\Desktop\NLP_Project\hate_spech\pipeline\prediction_pipeline.py] at line number [108] with error message [Error occurred in python script [C:\Users\MD RABIBUL ISLAM\Desktop\NLP_Project\hate_spech\pipeline\prediction_pipeline.py] at line number [84] with error message [Error occurred in python script [C:\Users\MD RABIBUL ISLAM\Desktop\NLP_Project\hate_spech\pipeline\prediction_pipeline.py] at line number [57] with error message [Model file not found at artifacts/PredictModel\model.h5]]]]
